<sdf version='1.6'>
  <world name='default'>
    <plugin name="welcome_message" filename="libwelcome_message.so"/>
    <light name='sun' type='directional'>
      <cast_shadows>1</cast_shadows>
      <pose frame=''>0 0 10 0 -0 0</pose>
      <diffuse>0.8 0.8 0.8 1</diffuse>
      <specular>0.2 0.2 0.2 1</specular>
      <attenuation>
        <range>1000</range>
        <constant>0.9</constant>
        <linear>0.01</linear>
        <quadratic>0.001</quadratic>
      </attenuation>
      <direction>-0.5 0.1 -0.9</direction>
    </light>
    <model name='ground_plane'>
      <static>1</static>
      <link name='link'>
        <collision name='collision'>
          <geometry>
            <plane>
              <normal>0 0 1</normal>
              <size>100 100</size>
            </plane>
          </geometry>
          <surface>
            <contact>
              <collide_bitmask>65535</collide_bitmask>
              <ode/>
            </contact>
            <friction>
              <ode>
                <mu>100</mu>
                <mu2>50</mu2>
              </ode>
              <torsional>
                <ode/>
              </torsional>
            </friction>
            <bounce/>
          </surface>
          <max_contacts>10</max_contacts>
        </collision>
        <visual name='visual'>
          <cast_shadows>0</cast_shadows>
          <geometry>
            <plane>
              <normal>0 0 1</normal>
              <size>100 100</size>
            </plane>
          </geometry>
          <material>
            <script>
              <uri>file://media/materials/scripts/gazebo.material</uri>
              <name>Gazebo/Grey</name>
            </script>
          </material>
        </visual>
        <self_collide>0</self_collide>
        <kinematic>0</kinematic>
      </link>
    </model>
    <gravity>0 0 -9.8</gravity>
    <magnetic_field>6e-06 2.3e-05 -4.2e-05</magnetic_field>
    <atmosphere type='adiabatic'/>
    <physics name='default_physics' default='0' type='ode'>
      <max_step_size>0.001</max_step_size>
      <real_time_factor>1</real_time_factor>
      <real_time_update_rate>1000</real_time_update_rate>
    </physics>
    <scene>
      <ambient>0.4 0.4 0.4 1</ambient>
      <background>0.7 0.7 0.7 1</background>
      <shadows>1</shadows>
    </scene>
    <spherical_coordinates>
      <surface_model>EARTH_WGS84</surface_model>
      <latitude_deg>0</latitude_deg>
      <longitude_deg>0</longitude_deg>
      <elevation>0</elevation>
      <heading_deg>0</heading_deg>
    </spherical_coordinates>
    <model name='ArmGripper'>
      <model name='simple_arm_gripper'>
        <link name='simple_arm::arm_base'>
          <inertial>
            <pose frame=''>0 0 0.00099 0 -0 0</pose>
            <inertia>
              <ixx>1.11</ixx>
              <ixy>0</ixy>
              <ixz>0</ixz>
              <iyy>100.11</iyy>
              <iyz>0</iyz>
              <izz>1.01</izz>
            </inertia>
            <mass>101</mass>
          </inertial>
          <collision name='arm_base_geom'>
            <pose frame=''>0 0 0.05 0 -0 0</pose>
            <geometry>
              <box>
                <size>1 1 0.1</size>
              </box>
            </geometry>
            <max_contacts>10</max_contacts>
            <surface>
              <contact>
                <ode/>
              </contact>
              <bounce/>
              <friction>
                <torsional>
                  <ode/>
                </torsional>
                <ode/>
              </friction>
            </surface>
          </collision>
          <visual name='arm_base_geom_visual'>
            <pose frame=''>0 0 0.05 0 -0 0</pose>
            <geometry>
              <box>
                <size>1 1 0.1</size>
              </box>
            </geometry>
            <material>
              <script>
                <uri>file://media/materials/scripts/gazebo.material</uri>
                <name>Gazebo/Blue</name>
              </script>
            </material>
          </visual>
          <collision name='arm_base_geom_arm_trunk'>
            <pose frame=''>0 0 0.6 0 -0 0</pose>
            <geometry>
              <cylinder>
                <radius>0.05</radius>
                <length>1</length>
              </cylinder>
            </geometry>
            <max_contacts>10</max_contacts>
            <surface>
              <contact>
                <ode/>
              </contact>
              <bounce/>
              <friction>
                <torsional>
                  <ode/>
                </torsional>
                <ode/>
              </friction>
            </surface>
          </collision>
          <visual name='arm_base_geom_arm_trunk_visual'>
            <pose frame=''>0 0 0.6 0 -0 0</pose>
            <geometry>
              <cylinder>
                <radius>0.05</radius>
                <length>1</length>
              </cylinder>
            </geometry>
            <material>
              <script>
                <uri>file://media/materials/scripts/gazebo.material</uri>
                <name>Gazebo/Red</name>
              </script>
            </material>
          </visual>
          <pose frame=''>0 0 0 0 -0 0</pose>
          <self_collide>0</self_collide>
          <kinematic>0</kinematic>
        </link>
        <link name='simple_arm::arm_shoulder_pan'>
          <pose frame=''>0 0 1.1 0 -0 0</pose>
          <inertial>
            <pose frame=''>0.045455 0 0 0 -0 0</pose>
            <inertia>
              <ixx>0.011</ixx>
              <ixy>0</ixy>
              <ixz>0</ixz>
              <iyy>0.0225</iyy>
              <iyz>0</iyz>
              <izz>0.0135</izz>
            </inertia>
            <mass>1.1</mass>
          </inertial>
          <collision name='arm_shoulder_pan_geom'>
            <pose frame=''>0 0 0.05 0 -0 0</pose>
            <geometry>
              <cylinder>
                <radius>0.05</radius>
                <length>0.1</length>
              </cylinder>
            </geometry>
            <max_contacts>10</max_contacts>
            <surface>
              <contact>
                <ode/>
              </contact>
              <bounce/>
              <friction>
                <torsional>
                  <ode/>
                </torsional>
                <ode/>
              </friction>
            </surface>
          </collision>
          <visual name='arm_shoulder_pan_geom_visual'>
            <pose frame=''>0 0 0.05 0 -0 0</pose>
            <geometry>
              <cylinder>
                <radius>0.05</radius>
                <length>0.1</length>
              </cylinder>
            </geometry>
            <material>
              <script>
                <uri>file://media/materials/scripts/gazebo.material</uri>
                <name>Gazebo/Yellow</name>
              </script>
            </material>
          </visual>
          <collision name='arm_shoulder_pan_geom_arm_shoulder'>
            <pose frame=''>0.55 0 0.05 0 -0 0</pose>
            <geometry>
              <box>
                <size>1 0.05 0.1</size>
              </box>
            </geometry>
            <max_contacts>10</max_contacts>
            <surface>
              <contact>
                <ode/>
              </contact>
              <bounce/>
              <friction>
                <torsional>
                  <ode/>
                </torsional>
                <ode/>
              </friction>
            </surface>
          </collision>
          <visual name='arm_shoulder_pan_geom_arm_shoulder_visual'>
            <pose frame=''>0.55 0 0.05 0 -0 0</pose>
            <geometry>
              <box>
                <size>1 0.05 0.1</size>
              </box>
            </geometry>
            <material>
              <script>
                <uri>file://media/materials/scripts/gazebo.material</uri>
                <name>Gazebo/Yellow</name>
              </script>
            </material>
          </visual>
          <self_collide>0</self_collide>
          <kinematic>0</kinematic>
        </link>
        <link name='simple_arm::arm_elbow_pan'>
          <pose frame=''>1.05 0 1.1 0 -0 0</pose>
          <inertial>
            <pose frame=''>0.0875 0 0.083333 0 -0 0</pose>
            <inertia>
              <ixx>0.031</ixx>
              <ixy>0</ixy>
              <ixz>0.005</ixz>
              <iyy>0.07275</iyy>
              <iyz>0</iyz>
              <izz>0.04475</izz>
            </inertia>
            <mass>1.2</mass>
          </inertial>
          <collision name='arm_elbow_pan_geom'>
            <pose frame=''>0 0 0.1 0 -0 0</pose>
            <geometry>
              <cylinder>
                <radius>0.05</radius>
                <length>0.2</length>
              </cylinder>
            </geometry>
            <max_contacts>10</max_contacts>
            <surface>
              <contact>
                <ode/>
              </contact>
              <bounce/>
              <friction>
                <torsional>
                  <ode/>
                </torsional>
                <ode/>
              </friction>
            </surface>
          </collision>
          <visual name='arm_elbow_pan_geom_visual'>
            <pose frame=''>0 0 0.1 0 -0 0</pose>
            <geometry>
              <cylinder>
                <radius>0.05</radius>
                <length>0.2</length>
              </cylinder>
            </geometry>
            <material>
              <script>
                <uri>file://media/materials/scripts/gazebo.material</uri>
                <name>Gazebo/Red</name>
              </script>
            </material>
          </visual>
          <collision name='arm_elbow_pan_geom_arm_elbow'>
            <pose frame=''>0.3 0 0.15 0 -0 0</pose>
            <geometry>
              <box>
                <size>0.5 0.03 0.1</size>
              </box>
            </geometry>
            <max_contacts>10</max_contacts>
            <surface>
              <contact>
                <ode/>
              </contact>
              <bounce/>
              <friction>
                <torsional>
                  <ode/>
                </torsional>
                <ode/>
              </friction>
            </surface>
          </collision>
          <visual name='arm_elbow_pan_geom_arm_elbow_visual'>
            <pose frame=''>0.3 0 0.15 0 -0 0</pose>
            <geometry>
              <box>
                <size>0.5 0.03 0.1</size>
              </box>
            </geometry>
            <material>
              <script>
                <uri>file://media/materials/scripts/gazebo.material</uri>
                <name>Gazebo/Yellow</name>
              </script>
            </material>
          </visual>
          <collision name='arm_elbow_pan_geom_arm_wrist'>
            <pose frame=''>0.55 0 0.15 0 -0 0</pose>
            <geometry>
              <cylinder>
                <radius>0.05</radius>
                <length>0.3</length>
              </cylinder>
            </geometry>
            <max_contacts>10</max_contacts>
            <surface>
              <contact>
                <ode/>
              </contact>
              <bounce/>
              <friction>
                <torsional>
                  <ode/>
                </torsional>
                <ode/>
              </friction>
            </surface>
          </collision>
          <visual name='arm_elbow_pan_geom_arm_wrist_visual'>
            <pose frame=''>0.55 0 0.15 0 -0 0</pose>
            <geometry>
              <cylinder>
                <radius>0.05</radius>
                <length>0.3</length>
              </cylinder>
            </geometry>
            <material>
              <script>
                <uri>file://media/materials/scripts/gazebo.material</uri>
                <name>Gazebo/Red</name>
              </script>
            </material>
          </visual>
          <self_collide>0</self_collide>
          <kinematic>0</kinematic>
        </link>
        <link name='simple_arm::arm_wrist_lift'>
          <pose frame=''>1.6 0 1.05 0 -0 0</pose>
          <inertial>
            <pose frame=''>0 0 0 0 -0 0</pose>
            <inertia>
              <ixx>0.01</ixx>
              <ixy>0</ixy>
              <ixz>0</ixz>
              <iyy>0.01</iyy>
              <iyz>0</iyz>
              <izz>0.001</izz>
            </inertia>
            <mass>0.1</mass>
          </inertial>
          <collision name='arm_wrist_lift_geom'>
            <pose frame=''>0 0 0.5 0 -0 0</pose>
            <geometry>
              <cylinder>
                <radius>0.03</radius>
                <length>1</length>
              </cylinder>
            </geometry>
            <max_contacts>10</max_contacts>
            <surface>
              <contact>
                <ode/>
              </contact>
              <bounce/>
              <friction>
                <torsional>
                  <ode/>
                </torsional>
                <ode/>
              </friction>
            </surface>
          </collision>
          <visual name='arm_wrist_lift_geom_visual'>
            <pose frame=''>0 0 0.5 0 -0 0</pose>
            <geometry>
              <cylinder>
                <radius>0.03</radius>
                <length>1</length>
              </cylinder>
            </geometry>
            <material>
              <script>
                <uri>file://media/materials/scripts/gazebo.material</uri>
                <name>Gazebo/Yellow</name>
              </script>
            </material>
          </visual>
          <self_collide>0</self_collide>
          <kinematic>0</kinematic>
        </link>
        <link name='simple_arm::arm_wrist_roll'>
          <pose frame=''>1.6 0 1 0 -0 0</pose>
          <inertial>
            <pose frame=''>0 0 0 0 -0 0</pose>
            <inertia>
              <ixx>0.01</ixx>
              <ixy>0</ixy>
              <ixz>0</ixz>
              <iyy>0.01</iyy>
              <iyz>0</iyz>
              <izz>0.001</izz>
            </inertia>
            <mass>0.1</mass>
          </inertial>
          <collision name='arm_wrist_roll_geom'>
            <pose frame=''>0 0 0.025 0 -0 0</pose>
            <geometry>
              <cylinder>
                <radius>0.05</radius>
                <length>0.05</length>
              </cylinder>
            </geometry>
            <max_contacts>10</max_contacts>
            <surface>
              <contact>
                <ode/>
              </contact>
              <bounce/>
              <friction>
                <torsional>
                  <ode/>
                </torsional>
                <ode/>
              </friction>
            </surface>
          </collision>
          <visual name='arm_wrist_roll_geom_visual'>
            <pose frame=''>0 0 0.025 0 -0 0</pose>
            <geometry>
              <cylinder>
                <radius>0.05</radius>
                <length>0.05</length>
              </cylinder>
            </geometry>
            <material>
              <script>
                <uri>file://media/materials/scripts/gazebo.material</uri>
                <name>Gazebo/Red</name>
              </script>
            </material>
          </visual>
          <self_collide>0</self_collide>
          <kinematic>0</kinematic>
        </link>
        <joint name='simple_arm::arm_shoulder_pan_joint' type='revolute'>
          <parent>simple_arm::arm_base</parent>
          <child>simple_arm::arm_shoulder_pan</child>
          <axis>
            <dynamics>
              <damping>1</damping>
              <friction>0</friction>
              <spring_reference>0</spring_reference>
              <spring_stiffness>0</spring_stiffness>
            </dynamics>
            <xyz>0 0 1</xyz>
            <use_parent_model_frame>1</use_parent_model_frame>
            <limit>
              <lower>-1e+16</lower>
              <upper>1e+16</upper>
            </limit>
          </axis>
        </joint>
        <joint name='simple_arm::arm_elbow_pan_joint' type='revolute'>
          <parent>simple_arm::arm_shoulder_pan</parent>
          <child>simple_arm::arm_elbow_pan</child>
          <axis>
            <dynamics>
              <damping>1</damping>
              <friction>0</friction>
              <spring_reference>0</spring_reference>
              <spring_stiffness>0</spring_stiffness>
            </dynamics>
            <xyz>0 0 1</xyz>
            <use_parent_model_frame>1</use_parent_model_frame>
            <limit>
              <lower>-1e+16</lower>
              <upper>1e+16</upper>
            </limit>
          </axis>
        </joint>
        <joint name='simple_arm::arm_wrist_lift_joint' type='prismatic'>
          <parent>simple_arm::arm_elbow_pan</parent>
          <child>simple_arm::arm_wrist_lift</child>
          <axis>
            <dynamics>
              <damping>1</damping>
              <friction>0</friction>
              <spring_reference>0</spring_reference>
              <spring_stiffness>0</spring_stiffness>
            </dynamics>
            <limit>
              <lower>-0.8</lower>
              <upper>0.1</upper>
            </limit>
            <xyz>0 0 1</xyz>
            <use_parent_model_frame>1</use_parent_model_frame>
          </axis>
        </joint>
        <joint name='simple_arm::arm_wrist_roll_joint' type='revolute'>
          <parent>simple_arm::arm_wrist_lift</parent>
          <child>simple_arm::arm_wrist_roll</child>
          <axis>
            <dynamics>
              <damping>1</damping>
              <friction>0</friction>
              <spring_reference>0</spring_reference>
              <spring_stiffness>0</spring_stiffness>
            </dynamics>
            <limit>
              <lower>-2.99999</lower>
              <upper>2.99999</upper>
            </limit>
            <xyz>0 0 1</xyz>
            <use_parent_model_frame>1</use_parent_model_frame>
          </axis>
        </joint>
        <link name='simple_gripper::riser'>
          <pose frame=''>1.65 0 1.5 0 -0 0</pose>
          <inertial>
            <mass>10</mass>
            <inertia>
              <ixx>1</ixx>
              <ixy>0</ixy>
              <ixz>0</ixz>
              <iyy>1</iyy>
              <iyz>0</iyz>
              <izz>1</izz>
            </inertia>
          </inertial>
          <collision name='collision'>
            <geometry>
              <box>
                <size>0.05 0.05 1</size>
              </box>
            </geometry>
            <surface>
              <contact>
                <ode>
                  <max_vel>0</max_vel>
                </ode>
              </contact>
              <bounce/>
              <friction>
                <torsional>
                  <ode/>
                </torsional>
                <ode/>
              </friction>
            </surface>
            <max_contacts>10</max_contacts>
          </collision>
          <visual name='visual'>
            <geometry>
              <box>
                <size>0.05 0.05 1</size>
              </box>
            </geometry>
          </visual>
          <self_collide>0</self_collide>
          <kinematic>0</kinematic>
        </link>
        <link name='simple_gripper::palm'>
          <pose frame=''>1.8 0 1.05 0 -0 0</pose>
          <inertial>
            <mass>0.5</mass>
            <inertia>
              <ixx>1</ixx>
              <ixy>0</ixy>
              <ixz>0</ixz>
              <iyy>1</iyy>
              <iyz>0</iyz>
              <izz>1</izz>
            </inertia>
          </inertial>
          <collision name='collision'>
            <geometry>
              <box>
                <size>0.1 0.2 0.1</size>
              </box>
            </geometry>
            <surface>
              <contact>
                <ode>
                  <max_vel>0</max_vel>
                </ode>
              </contact>
              <bounce/>
              <friction>
                <torsional>
                  <ode/>
                </torsional>
                <ode/>
              </friction>
            </surface>
            <max_contacts>10</max_contacts>
          </collision>
          <visual name='visual'>
            <geometry>
              <box>
                <size>0.1 0.2 0.1</size>
              </box>
            </geometry>
          </visual>
          <self_collide>0</self_collide>
          <kinematic>0</kinematic>
        </link>
        <link name='simple_gripper::left_finger'>
          <pose frame=''>1.9 0.2 1.05 0 0 -0.78539</pose>
          <inertial>
            <mass>0.1</mass>
            <inertia>
              <ixx>1</ixx>
              <ixy>0</ixy>
              <ixz>0</ixz>
              <iyy>1</iyy>
              <iyz>0</iyz>
              <izz>1</izz>
            </inertia>
          </inertial>
          <collision name='collision'>
            <geometry>
              <box>
                <size>0.1 0.3 0.1</size>
              </box>
            </geometry>
            <surface>
              <friction>
                <ode>
                  <mu>0.1</mu>
                  <mu2>0</mu2>
                </ode>
                <torsional>
                  <ode/>
                </torsional>
              </friction>
              <contact>
                <ode>
                  <max_vel>0</max_vel>
                </ode>
              </contact>
              <bounce/>
            </surface>
            <max_contacts>10</max_contacts>
          </collision>
          <visual name='visual'>
            <geometry>
              <box>
                <size>0.1 0.3 0.1</size>
              </box>
            </geometry>
          </visual>
          <self_collide>0</self_collide>
          <kinematic>0</kinematic>
        </link>
        <link name='simple_gripper::left_finger_tip'>
          <pose frame=''>2.136 0.3 1.05 0 -0 1.5707</pose>
          <inertial>
            <mass>0.5</mass>
            <inertia>
              <ixx>1</ixx>
              <ixy>0</ixy>
              <ixz>0</ixz>
              <iyy>1</iyy>
              <iyz>0</iyz>
              <izz>1</izz>
            </inertia>
          </inertial>
          <collision name='collision'>
            <geometry>
              <box>
                <size>0.1 0.2 0.1</size>
              </box>
            </geometry>
            <surface>
              <friction>
                <ode>
                  <mu>0.1</mu>
                  <mu2>0</mu2>
                </ode>
                <torsional>
                  <ode/>
                </torsional>
              </friction>
              <contact>
                <ode>
                  <max_vel>0</max_vel>
                </ode>
              </contact>
              <bounce/>
            </surface>
            <max_contacts>10</max_contacts>
          </collision>
          <visual name='visual'>
            <geometry>
              <box>
                <size>0.1 0.2 0.1</size>
              </box>
            </geometry>
          </visual>
          <self_collide>0</self_collide>
          <kinematic>0</kinematic>
        </link>
        <link name='simple_gripper::right_finger'>
          <pose frame=''>1.9 -0.2 1.05 0 -0 0.78539</pose>
          <inertial>
            <mass>0.1</mass>
            <inertia>
              <ixx>1</ixx>
              <ixy>0</ixy>
              <ixz>0</ixz>
              <iyy>1</iyy>
              <iyz>0</iyz>
              <izz>1</izz>
            </inertia>
          </inertial>
          <collision name='collision'>
            <geometry>
              <box>
                <size>0.1 0.3 0.1</size>
              </box>
            </geometry>
            <surface>
              <friction>
                <ode>
                  <mu>0.1</mu>
                  <mu2>0</mu2>
                </ode>
                <torsional>
                  <ode/>
                </torsional>
              </friction>
              <contact>
                <ode>
                  <max_vel>0</max_vel>
                </ode>
              </contact>
              <bounce/>
            </surface>
            <max_contacts>10</max_contacts>
          </collision>
          <visual name='visual'>
            <geometry>
              <box>
                <size>0.1 0.3 0.1</size>
              </box>
            </geometry>
          </visual>
          <self_collide>0</self_collide>
          <kinematic>0</kinematic>
        </link>
        <link name='simple_gripper::right_finger_tip'>
          <pose frame=''>2.136 -0.3 1.05 0 -0 1.5707</pose>
          <inertial>
            <mass>0.1</mass>
            <inertia>
              <ixx>1</ixx>
              <ixy>0</ixy>
              <ixz>0</ixz>
              <iyy>1</iyy>
              <iyz>0</iyz>
              <izz>1</izz>
            </inertia>
          </inertial>
          <collision name='collision'>
            <geometry>
              <box>
                <size>0.1 0.2 0.1</size>
              </box>
            </geometry>
            <surface>
              <friction>
                <ode>
                  <mu>0.1</mu>
                  <mu2>0</mu2>
                </ode>
                <torsional>
                  <ode/>
                </torsional>
              </friction>
              <contact>
                <ode>
                  <max_vel>0</max_vel>
                </ode>
              </contact>
              <bounce/>
            </surface>
            <max_contacts>10</max_contacts>
          </collision>
          <visual name='visual'>
            <geometry>
              <box>
                <size>0.1 0.2 0.1</size>
              </box>
            </geometry>
          </visual>
          <self_collide>0</self_collide>
          <kinematic>0</kinematic>
        </link>
        <joint name='simple_gripper::palm_left_finger' type='revolute'>
          <pose frame=''>0 -0.15 0 0 -0 0</pose>
          <child>simple_gripper::left_finger</child>
          <parent>simple_gripper::palm</parent>
          <axis>
            <limit>
              <lower>-0.8</lower>
              <upper>0.8</upper>
            </limit>
            <xyz>0 0 1</xyz>
            <use_parent_model_frame>1</use_parent_model_frame>
            <dynamics>
              <spring_reference>0</spring_reference>
              <spring_stiffness>0</spring_stiffness>
            </dynamics>
          </axis>
        </joint>
        <joint name='simple_gripper::left_finger_tip' type='revolute'>
          <pose frame=''>0 0.1 0 0 -0 0</pose>
          <child>simple_gripper::left_finger_tip</child>
          <parent>simple_gripper::left_finger</parent>
          <axis>
            <limit>
              <lower>-0.8</lower>
              <upper>0.8</upper>
            </limit>
            <xyz>0 0 1</xyz>
            <use_parent_model_frame>1</use_parent_model_frame>
            <dynamics>
              <spring_reference>0</spring_reference>
              <spring_stiffness>0</spring_stiffness>
            </dynamics>
          </axis>
        </joint>
        <joint name='simple_gripper::palm_right_finger' type='revolute'>
          <pose frame=''>0 0.15 0 0 -0 0</pose>
          <child>simple_gripper::right_finger</child>
          <parent>simple_gripper::palm</parent>
          <axis>
            <limit>
              <lower>-0.8</lower>
              <upper>0.8</upper>
            </limit>
            <xyz>0 0 1</xyz>
            <use_parent_model_frame>1</use_parent_model_frame>
            <dynamics>
              <spring_reference>0</spring_reference>
              <spring_stiffness>0</spring_stiffness>
            </dynamics>
          </axis>
        </joint>
        <joint name='simple_gripper::right_finger_tip' type='revolute'>
          <pose frame=''>0 0.1 0 0 -0 0</pose>
          <child>simple_gripper::right_finger_tip</child>
          <parent>simple_gripper::right_finger</parent>
          <axis>
            <limit>
              <lower>-0.8</lower>
              <upper>0.8</upper>
            </limit>
            <xyz>0 0 1</xyz>
            <use_parent_model_frame>1</use_parent_model_frame>
            <dynamics>
              <spring_reference>0</spring_reference>
              <spring_stiffness>0</spring_stiffness>
            </dynamics>
          </axis>
        </joint>
        <joint name='simple_gripper::palm_riser' type='prismatic'>
          <child>simple_gripper::palm</child>
          <parent>simple_gripper::riser</parent>
          <axis>
            <limit>
              <lower>0</lower>
              <upper>0.9</upper>
            </limit>
            <xyz>0 0 1</xyz>
            <use_parent_model_frame>1</use_parent_model_frame>
            <dynamics>
              <spring_reference>0</spring_reference>
              <spring_stiffness>0</spring_stiffness>
            </dynamics>
          </axis>
        </joint>
        <gripper name='simple_gripper'>
          <grasp_check>
            <detach_steps>40</detach_steps>
            <attach_steps>20</attach_steps>
            <min_contact_count>2</min_contact_count>
          </grasp_check>
          <gripper_link>simple_gripper::right_finger</gripper_link>
          <gripper_link>simple_gripper::right_finger_tip</gripper_link>
          <gripper_link>simple_gripper::left_finger</gripper_link>
          <gripper_link>simple_gripper::left_finger_tip</gripper_link>
          <palm_link>simple_gripper::palm</palm_link>
        </gripper>
        <plugin name='simple_arm_plugin' filename='libJointTrajectoryPlugin.so'/>
        <joint name='arm_gripper_joint' type='revolute'>
          <parent>simple_arm::arm_wrist_roll</parent>
          <child>simple_gripper::riser</child>
          <axis>
            <limit>
              <lower>0</lower>
              <upper>0</upper>
            </limit>
            <xyz>0 0 1</xyz>
            <use_parent_model_frame>1</use_parent_model_frame>
            <dynamics>
              <spring_reference>0</spring_reference>
              <spring_stiffness>0</spring_stiffness>
            </dynamics>
          </axis>
        </joint>
        <pose frame=''>0.463373 0.662981 0 0 -0 0</pose>
      </model>
      <static>0</static>
      <allow_auto_disable>1</allow_auto_disable>
      <pose frame=''>0 0 0 0 -0 0</pose>
    </model>
    <state world_name='default'>
      <sim_time>93 860000000</sim_time>
      <real_time>91 284538889</real_time>
      <wall_time>1598854589 395391616</wall_time>
      <iterations>93860</iterations>
      <model name='ArmGripper'>
        <pose frame=''>0 0 0 0 -0 0</pose>
        <scale>1 1 1</scale>
        <model name='simple_arm_gripper'>
          <pose frame=''>0.463373 0.662981 0 0 -0 0</pose>
          <scale>1 1 1</scale>
          <link name='simple_arm::arm_base'>
            <pose frame=''>0.463373 0.662981 0 0 -0 0</pose>
            <velocity>0 0 0 0 -0 0</velocity>
            <acceleration>0 0 0 0 -0 0</acceleration>
            <wrench>0 0 0 0 -0 0</wrench>
          </link>
          <link name='simple_arm::arm_elbow_pan'>
            <pose frame=''>1.51337 0.662981 1.1 0 -0 0</pose>
            <velocity>0 0 0 0 -0 0</velocity>
            <acceleration>0 0 0 0 -0 0</acceleration>
            <wrench>0 0 0 0 -0 0</wrench>
          </link>
          <link name='simple_arm::arm_shoulder_pan'>
            <pose frame=''>0.463373 0.662981 1.1 0 -0 0</pose>
            <velocity>0 0 0 0 -0 0</velocity>
            <acceleration>0 0 0 0 -0 0</acceleration>
            <wrench>0 0 0 0 -0 0</wrench>
          </link>
          <link name='simple_arm::arm_wrist_lift'>
            <pose frame=''>2.06337 0.662981 1.05 0 -0 0</pose>
            <velocity>0 0 0 0 -0 0</velocity>
            <acceleration>0 0 0 0 -0 0</acceleration>
            <wrench>0 0 0 0 -0 0</wrench>
          </link>
          <link name='simple_arm::arm_wrist_roll'>
            <pose frame=''>2.06337 0.662981 1 0 -0 0</pose>
            <velocity>0 0 0 0 -0 0</velocity>
            <acceleration>0 0 0 0 -0 0</acceleration>
            <wrench>0 0 0 0 -0 0</wrench>
          </link>
          <link name='simple_gripper::left_finger'>
            <pose frame=''>2.36337 0.862981 1.05 0 0 -0.78539</pose>
            <velocity>0 0 0 0 -0 0</velocity>
            <acceleration>0 0 0 0 -0 0</acceleration>
            <wrench>0 0 0 0 -0 0</wrench>
          </link>
          <link name='simple_gripper::left_finger_tip'>
            <pose frame=''>2.59937 0.962981 1.05 0 -0 1.5707</pose>
            <velocity>0 0 0 0 -0 0</velocity>
            <acceleration>0 0 0 0 -0 0</acceleration>
            <wrench>0 0 0 0 -0 0</wrench>
          </link>
          <link name='simple_gripper::palm'>
            <pose frame=''>2.26337 0.662981 1.05 0 -0 0</pose>
            <velocity>0 0 0 0 -0 0</velocity>
            <acceleration>0 0 0 0 -0 0</acceleration>
            <wrench>0 0 0 0 -0 0</wrench>
          </link>
          <link name='simple_gripper::right_finger'>
            <pose frame=''>2.36337 0.462981 1.05 0 -0 0.78539</pose>
            <velocity>0 0 0 0 -0 0</velocity>
            <acceleration>0 0 0 0 -0 0</acceleration>
            <wrench>0 0 0 0 -0 0</wrench>
          </link>
          <link name='simple_gripper::right_finger_tip'>
            <pose frame=''>2.59937 0.362981 1.05 0 -0 1.5707</pose>
            <velocity>0 0 0 0 -0 0</velocity>
            <acceleration>0 0 0 0 -0 0</acceleration>
            <wrench>0 0 0 0 -0 0</wrench>
          </link>
          <link name='simple_gripper::riser'>
            <pose frame=''>2.11337 0.662981 1.5 0 -0 0</pose>
            <velocity>0 0 0 0 -0 0</velocity>
            <acceleration>0 0 0 0 -0 0</acceleration>
            <wrench>0 0 0 0 -0 0</wrench>
          </link>
        </model>
      </model>
      <model name='ground_plane'>
        <pose frame=''>0 0 0 0 -0 0</pose>
        <scale>1 1 1</scale>
        <link name='link'>
          <pose frame=''>0 0 0 0 -0 0</pose>
          <velocity>0 0 0 0 -0 0</velocity>
          <acceleration>0 0 0 0 -0 0</acceleration>
          <wrench>0 0 0 0 -0 0</wrench>
        </link>
      </model>
      <light name='sun'>
        <pose frame=''>0 0 10 0 -0 0</pose>
      </light>
    </state>
    <gui fullscreen='0'>
      <camera name='user_camera'>
        <pose frame=''>5.00634 -1.48197 2.0141 0 0.275643 2.35619</pose>
        <view_controller>orbit</view_controller>
        <projection_type>perspective</projection_type>
      </camera>
    </gui>
  </world>
</sdf>
